[2025-04-27T04:01:37.551+0000] {taskinstance.py:1956} INFO - Dependencies all met for dep_context=non-requeueable deps ti=<TaskInstance: ingestao_chuva_15min.carregar_dados scheduled__2025-04-27T03:45:00+00:00 [queued]>
[2025-04-27T04:01:37.556+0000] {taskinstance.py:1956} INFO - Dependencies all met for dep_context=requeueable deps ti=<TaskInstance: ingestao_chuva_15min.carregar_dados scheduled__2025-04-27T03:45:00+00:00 [queued]>
[2025-04-27T04:01:37.556+0000] {taskinstance.py:2170} INFO - Starting attempt 1 of 2
[2025-04-27T04:01:37.563+0000] {taskinstance.py:2191} INFO - Executing <Task(PythonOperator): carregar_dados> on 2025-04-27 03:45:00+00:00
[2025-04-27T04:01:37.566+0000] {standard_task_runner.py:60} INFO - Started process 212 to run task
[2025-04-27T04:01:37.568+0000] {standard_task_runner.py:87} INFO - Running: ['***', 'tasks', 'run', 'ingestao_chuva_15min', 'carregar_dados', 'scheduled__2025-04-27T03:45:00+00:00', '--job-id', '149', '--raw', '--subdir', 'DAGS_FOLDER/ingestao_chuva_15min.py', '--cfg-path', '/tmp/tmpibi3cblf']
[2025-04-27T04:01:37.569+0000] {standard_task_runner.py:88} INFO - Job 149: Subtask carregar_dados
[2025-04-27T04:01:37.596+0000] {task_command.py:423} INFO - Running <TaskInstance: ingestao_chuva_15min.carregar_dados scheduled__2025-04-27T03:45:00+00:00 [running]> on host ab7547454922
[2025-04-27T04:01:37.644+0000] {taskinstance.py:2480} INFO - Exporting env vars: AIRFLOW_CTX_DAG_OWNER='***' AIRFLOW_CTX_DAG_ID='ingestao_chuva_15min' AIRFLOW_CTX_TASK_ID='carregar_dados' AIRFLOW_CTX_EXECUTION_DATE='2025-04-27T03:45:00+00:00' AIRFLOW_CTX_TRY_NUMBER='1' AIRFLOW_CTX_DAG_RUN_ID='scheduled__2025-04-27T03:45:00+00:00'
[2025-04-27T04:01:37.649+0000] {taskinstance.py:2698} ERROR - Task failed with exception
Traceback (most recent call last):
  File "/home/airflow/.local/lib/python3.8/site-packages/airflow/models/taskinstance.py", line 433, in _execute_task
    result = execute_callable(context=context, **execute_callable_kwargs)
  File "/home/airflow/.local/lib/python3.8/site-packages/airflow/operators/python.py", line 199, in execute
    return_value = self.execute_callable()
  File "/home/airflow/.local/lib/python3.8/site-packages/airflow/operators/python.py", line 216, in execute_callable
    return self.python_callable(*self.op_args, **self.op_kwargs)
  File "/opt/airflow/dags/etl/load.py", line 19, in carregar_parquets_para_duckdb
    con = duckdb.connect(duckdb_path)
duckdb.duckdb.IOException: IO Error: Cannot open file "/opt/***/data/db/duckdb_database.db": Permission denied
[2025-04-27T04:01:37.654+0000] {taskinstance.py:1138} INFO - Marking task as UP_FOR_RETRY. dag_id=ingestao_chuva_15min, task_id=carregar_dados, execution_date=20250427T034500, start_date=20250427T040137, end_date=20250427T040137
[2025-04-27T04:01:37.661+0000] {standard_task_runner.py:107} ERROR - Failed to execute job 149 for task carregar_dados (IO Error: Cannot open file "/opt/***/data/db/duckdb_database.db": Permission denied; 212)
[2025-04-27T04:01:37.699+0000] {local_task_job_runner.py:234} INFO - Task exited with return code 1
[2025-04-27T04:01:37.711+0000] {taskinstance.py:3280} INFO - 0 downstream tasks scheduled from follow-on schedule check
