[2025-04-27T02:47:41.586+0000] {taskinstance.py:1956} INFO - Dependencies all met for dep_context=non-requeueable deps ti=<TaskInstance: ingestao_chuva_15min.transformar_dados scheduled__2025-04-27T02:30:00+00:00 [queued]>
[2025-04-27T02:47:41.591+0000] {taskinstance.py:1956} INFO - Dependencies all met for dep_context=requeueable deps ti=<TaskInstance: ingestao_chuva_15min.transformar_dados scheduled__2025-04-27T02:30:00+00:00 [queued]>
[2025-04-27T02:47:41.592+0000] {taskinstance.py:2170} INFO - Starting attempt 1 of 2
[2025-04-27T02:47:41.600+0000] {taskinstance.py:2191} INFO - Executing <Task(PythonOperator): transformar_dados> on 2025-04-27 02:30:00+00:00
[2025-04-27T02:47:41.603+0000] {standard_task_runner.py:60} INFO - Started process 219 to run task
[2025-04-27T02:47:41.605+0000] {standard_task_runner.py:87} INFO - Running: ['***', 'tasks', 'run', 'ingestao_chuva_15min', 'transformar_dados', 'scheduled__2025-04-27T02:30:00+00:00', '--job-id', '111', '--raw', '--subdir', 'DAGS_FOLDER/ingestao_chuva_15min.py', '--cfg-path', '/tmp/tmpc3re1665']
[2025-04-27T02:47:41.606+0000] {standard_task_runner.py:88} INFO - Job 111: Subtask transformar_dados
[2025-04-27T02:47:41.639+0000] {task_command.py:423} INFO - Running <TaskInstance: ingestao_chuva_15min.transformar_dados scheduled__2025-04-27T02:30:00+00:00 [running]> on host 2dd2145e61aa
[2025-04-27T02:47:41.701+0000] {taskinstance.py:2480} INFO - Exporting env vars: AIRFLOW_CTX_DAG_OWNER='***' AIRFLOW_CTX_DAG_ID='ingestao_chuva_15min' AIRFLOW_CTX_TASK_ID='transformar_dados' AIRFLOW_CTX_EXECUTION_DATE='2025-04-27T02:30:00+00:00' AIRFLOW_CTX_TRY_NUMBER='1' AIRFLOW_CTX_DAG_RUN_ID='scheduled__2025-04-27T02:30:00+00:00'
[2025-04-27T02:47:41.703+0000] {logging_mixin.py:188} INFO - [clima_pluviometro] ðŸ”µ Processando: data/landing/clima_pluviometro/ano=2025/mes=04/dia=27/hora=02/clima_pluviometro_20250427_024738.json
[2025-04-27T02:47:42.247+0000] {taskinstance.py:2698} ERROR - Task failed with exception
Traceback (most recent call last):
  File "/home/airflow/.local/lib/python3.8/site-packages/airflow/models/taskinstance.py", line 433, in _execute_task
    result = execute_callable(context=context, **execute_callable_kwargs)
  File "/home/airflow/.local/lib/python3.8/site-packages/airflow/operators/python.py", line 199, in execute
    return_value = self.execute_callable()
  File "/home/airflow/.local/lib/python3.8/site-packages/airflow/operators/python.py", line 216, in execute_callable
    return self.python_callable(*self.op_args, **self.op_kwargs)
  File "/opt/airflow/dags/etl/transform.py", line 50, in transformar_json_para_parquet
    con.execute(f"COPY temp TO '{caminho_parquet}' (FORMAT 'parquet')")
duckdb.duckdb.IOException: IO Error: Could not set lock on file "data/bronze/clima_pluviometro/ano=2025/mes=04/dia=27/hora=02/clima_pluviometro_20250427_024742.parquet": Conflicting lock is held in /usr/local/bin/python3.8 (PID 205). See also https://duckdb.org/docs/connect/concurrency
[2025-04-27T02:47:42.253+0000] {taskinstance.py:1138} INFO - Marking task as UP_FOR_RETRY. dag_id=ingestao_chuva_15min, task_id=transformar_dados, execution_date=20250427T023000, start_date=20250427T024741, end_date=20250427T024742
[2025-04-27T02:47:42.261+0000] {standard_task_runner.py:107} ERROR - Failed to execute job 111 for task transformar_dados (IO Error: Could not set lock on file "data/bronze/clima_pluviometro/ano=2025/mes=04/dia=27/hora=02/clima_pluviometro_20250427_024742.parquet": Conflicting lock is held in /usr/local/bin/python3.8 (PID 205). See also https://duckdb.org/docs/connect/concurrency; 219)
[2025-04-27T02:47:42.298+0000] {local_task_job_runner.py:234} INFO - Task exited with return code 1
[2025-04-27T02:47:42.312+0000] {taskinstance.py:3280} INFO - 0 downstream tasks scheduled from follow-on schedule check
