[2025-04-30T13:24:23.939+0000] {taskinstance.py:1956} INFO - Dependencies all met for dep_context=non-requeueable deps ti=<TaskInstance: clima_radar_precipitacao_15min.carregar_dados_precipitacao_15min manual__2025-04-30T13:24:19.741242+00:00 [queued]>
[2025-04-30T13:24:23.945+0000] {taskinstance.py:1956} INFO - Dependencies all met for dep_context=requeueable deps ti=<TaskInstance: clima_radar_precipitacao_15min.carregar_dados_precipitacao_15min manual__2025-04-30T13:24:19.741242+00:00 [queued]>
[2025-04-30T13:24:23.946+0000] {taskinstance.py:2170} INFO - Starting attempt 1 of 1
[2025-04-30T13:24:23.956+0000] {taskinstance.py:2191} INFO - Executing <Task(PythonOperator): carregar_dados_precipitacao_15min> on 2025-04-30 13:24:19.741242+00:00
[2025-04-30T13:24:23.959+0000] {standard_task_runner.py:60} INFO - Started process 357 to run task
[2025-04-30T13:24:23.961+0000] {standard_task_runner.py:87} INFO - Running: ['***', 'tasks', 'run', 'clima_radar_precipitacao_15min', 'carregar_dados_precipitacao_15min', 'manual__2025-04-30T13:24:19.741242+00:00', '--job-id', '252', '--raw', '--subdir', 'DAGS_FOLDER/clima_radar.py', '--cfg-path', '/tmp/tmpwdo1eso0']
[2025-04-30T13:24:23.963+0000] {standard_task_runner.py:88} INFO - Job 252: Subtask carregar_dados_precipitacao_15min
[2025-04-30T13:24:23.993+0000] {task_command.py:423} INFO - Running <TaskInstance: clima_radar_precipitacao_15min.carregar_dados_precipitacao_15min manual__2025-04-30T13:24:19.741242+00:00 [running]> on host 81c910e0b178
[2025-04-30T13:24:24.052+0000] {taskinstance.py:2480} INFO - Exporting env vars: AIRFLOW_CTX_DAG_OWNER='***' AIRFLOW_CTX_DAG_ID='clima_radar_precipitacao_15min' AIRFLOW_CTX_TASK_ID='carregar_dados_precipitacao_15min' AIRFLOW_CTX_EXECUTION_DATE='2025-04-30T13:24:19.741242+00:00' AIRFLOW_CTX_TRY_NUMBER='1' AIRFLOW_CTX_DAG_RUN_ID='manual__2025-04-30T13:24:19.741242+00:00'
[2025-04-30T13:24:24.059+0000] {taskinstance.py:2698} ERROR - Task failed with exception
Traceback (most recent call last):
  File "/home/airflow/.local/lib/python3.8/site-packages/airflow/models/taskinstance.py", line 433, in _execute_task
    result = execute_callable(context=context, **execute_callable_kwargs)
  File "/home/airflow/.local/lib/python3.8/site-packages/airflow/operators/python.py", line 199, in execute
    return_value = self.execute_callable()
  File "/home/airflow/.local/lib/python3.8/site-packages/airflow/operators/python.py", line 216, in execute_callable
    return self.python_callable(*self.op_args, **self.op_kwargs)
  File "/opt/airflow/dags/etl/load.py", line 14, in carregar_parquets_para_duckdb
    con = duckdb.connect(duckdb_path)
duckdb.duckdb.IOException: IO Error: Could not set lock on file "/opt/***/data/db/duckdb_database.db": Conflicting lock is held in /usr/local/bin/python3.8 (PID 358). See also https://duckdb.org/docs/connect/concurrency
[2025-04-30T13:24:24.065+0000] {taskinstance.py:1138} INFO - Marking task as FAILED. dag_id=clima_radar_precipitacao_15min, task_id=carregar_dados_precipitacao_15min, execution_date=20250430T132419, start_date=20250430T132423, end_date=20250430T132424
[2025-04-30T13:24:24.075+0000] {standard_task_runner.py:107} ERROR - Failed to execute job 252 for task carregar_dados_precipitacao_15min (IO Error: Could not set lock on file "/opt/***/data/db/duckdb_database.db": Conflicting lock is held in /usr/local/bin/python3.8 (PID 358). See also https://duckdb.org/docs/connect/concurrency; 357)
[2025-04-30T13:24:24.093+0000] {local_task_job_runner.py:234} INFO - Task exited with return code 1
[2025-04-30T13:24:24.108+0000] {taskinstance.py:3280} INFO - 0 downstream tasks scheduled from follow-on schedule check
