[2025-04-27T03:24:42.868+0000] {taskinstance.py:1956} INFO - Dependencies all met for dep_context=non-requeueable deps ti=<TaskInstance: ingestao_chuva_15min.carregar_dados manual__2025-04-27T03:24:38.211638+00:00 [queued]>
[2025-04-27T03:24:42.874+0000] {taskinstance.py:1956} INFO - Dependencies all met for dep_context=requeueable deps ti=<TaskInstance: ingestao_chuva_15min.carregar_dados manual__2025-04-27T03:24:38.211638+00:00 [queued]>
[2025-04-27T03:24:42.875+0000] {taskinstance.py:2170} INFO - Starting attempt 1 of 2
[2025-04-27T03:24:42.883+0000] {taskinstance.py:2191} INFO - Executing <Task(PythonOperator): carregar_dados> on 2025-04-27 03:24:38.211638+00:00
[2025-04-27T03:24:42.886+0000] {standard_task_runner.py:60} INFO - Started process 409 to run task
[2025-04-27T03:24:42.888+0000] {standard_task_runner.py:87} INFO - Running: ['***', 'tasks', 'run', 'ingestao_chuva_15min', 'carregar_dados', 'manual__2025-04-27T03:24:38.211638+00:00', '--job-id', '131', '--raw', '--subdir', 'DAGS_FOLDER/ingestao_chuva_15min.py', '--cfg-path', '/tmp/tmpd5vbo3gs']
[2025-04-27T03:24:42.889+0000] {standard_task_runner.py:88} INFO - Job 131: Subtask carregar_dados
[2025-04-27T03:24:42.918+0000] {task_command.py:423} INFO - Running <TaskInstance: ingestao_chuva_15min.carregar_dados manual__2025-04-27T03:24:38.211638+00:00 [running]> on host 95deed28f92a
[2025-04-27T03:24:42.969+0000] {taskinstance.py:2480} INFO - Exporting env vars: AIRFLOW_CTX_DAG_OWNER='***' AIRFLOW_CTX_DAG_ID='ingestao_chuva_15min' AIRFLOW_CTX_TASK_ID='carregar_dados' AIRFLOW_CTX_EXECUTION_DATE='2025-04-27T03:24:38.211638+00:00' AIRFLOW_CTX_TRY_NUMBER='1' AIRFLOW_CTX_DAG_RUN_ID='manual__2025-04-27T03:24:38.211638+00:00'
[2025-04-27T03:24:42.979+0000] {taskinstance.py:2698} ERROR - Task failed with exception
Traceback (most recent call last):
  File "/home/airflow/.local/lib/python3.8/site-packages/airflow/models/taskinstance.py", line 433, in _execute_task
    result = execute_callable(context=context, **execute_callable_kwargs)
  File "/home/airflow/.local/lib/python3.8/site-packages/airflow/operators/python.py", line 199, in execute
    return_value = self.execute_callable()
  File "/home/airflow/.local/lib/python3.8/site-packages/airflow/operators/python.py", line 216, in execute_callable
    return self.python_callable(*self.op_args, **self.op_kwargs)
  File "/opt/airflow/dags/etl/load.py", line 18, in carregar_parquets_para_duckdb
    con = duckdb.connect(duckdb_path)
duckdb.duckdb.IOException: IO Error: Could not set lock on file "/opt/***/data/db/duckdb_database.db": Conflicting lock is held in PID 0. See also https://duckdb.org/docs/connect/concurrency
[2025-04-27T03:24:42.987+0000] {taskinstance.py:1138} INFO - Marking task as UP_FOR_RETRY. dag_id=ingestao_chuva_15min, task_id=carregar_dados, execution_date=20250427T032438, start_date=20250427T032442, end_date=20250427T032442
[2025-04-27T03:24:42.996+0000] {standard_task_runner.py:107} ERROR - Failed to execute job 131 for task carregar_dados (IO Error: Could not set lock on file "/opt/***/data/db/duckdb_database.db": Conflicting lock is held in PID 0. See also https://duckdb.org/docs/connect/concurrency; 409)
[2025-04-27T03:24:43.020+0000] {local_task_job_runner.py:234} INFO - Task exited with return code 1
[2025-04-27T03:24:43.032+0000] {taskinstance.py:3280} INFO - 0 downstream tasks scheduled from follow-on schedule check
