[2025-04-30T13:24:25.458+0000] {taskinstance.py:1956} INFO - Dependencies all met for dep_context=non-requeueable deps ti=<TaskInstance: adm_cor_comando_ocorrencias_abertas.carregar_dados_ocorrencias_abertas manual__2025-04-30T13:24:11.901982+00:00 [queued]>
[2025-04-30T13:24:25.463+0000] {taskinstance.py:1956} INFO - Dependencies all met for dep_context=requeueable deps ti=<TaskInstance: adm_cor_comando_ocorrencias_abertas.carregar_dados_ocorrencias_abertas manual__2025-04-30T13:24:11.901982+00:00 [queued]>
[2025-04-30T13:24:25.464+0000] {taskinstance.py:2170} INFO - Starting attempt 1 of 1
[2025-04-30T13:24:25.472+0000] {taskinstance.py:2191} INFO - Executing <Task(PythonOperator): carregar_dados_ocorrencias_abertas> on 2025-04-30 13:24:11.901982+00:00
[2025-04-30T13:24:25.475+0000] {standard_task_runner.py:60} INFO - Started process 391 to run task
[2025-04-30T13:24:25.477+0000] {standard_task_runner.py:87} INFO - Running: ['***', 'tasks', 'run', 'adm_cor_comando_ocorrencias_abertas', 'carregar_dados_ocorrencias_abertas', 'manual__2025-04-30T13:24:11.901982+00:00', '--job-id', '258', '--raw', '--subdir', 'DAGS_FOLDER/adm_cor_comando.py', '--cfg-path', '/tmp/tmpilthnvlw']
[2025-04-30T13:24:25.479+0000] {standard_task_runner.py:88} INFO - Job 258: Subtask carregar_dados_ocorrencias_abertas
[2025-04-30T13:24:25.506+0000] {task_command.py:423} INFO - Running <TaskInstance: adm_cor_comando_ocorrencias_abertas.carregar_dados_ocorrencias_abertas manual__2025-04-30T13:24:11.901982+00:00 [running]> on host 81c910e0b178
[2025-04-30T13:24:25.559+0000] {taskinstance.py:2480} INFO - Exporting env vars: AIRFLOW_CTX_DAG_OWNER='***' AIRFLOW_CTX_DAG_ID='adm_cor_comando_ocorrencias_abertas' AIRFLOW_CTX_TASK_ID='carregar_dados_ocorrencias_abertas' AIRFLOW_CTX_EXECUTION_DATE='2025-04-30T13:24:11.901982+00:00' AIRFLOW_CTX_TRY_NUMBER='1' AIRFLOW_CTX_DAG_RUN_ID='manual__2025-04-30T13:24:11.901982+00:00'
[2025-04-30T13:24:25.563+0000] {taskinstance.py:2698} ERROR - Task failed with exception
Traceback (most recent call last):
  File "/home/airflow/.local/lib/python3.8/site-packages/airflow/models/taskinstance.py", line 433, in _execute_task
    result = execute_callable(context=context, **execute_callable_kwargs)
  File "/home/airflow/.local/lib/python3.8/site-packages/airflow/operators/python.py", line 199, in execute
    return_value = self.execute_callable()
  File "/home/airflow/.local/lib/python3.8/site-packages/airflow/operators/python.py", line 216, in execute_callable
    return self.python_callable(*self.op_args, **self.op_kwargs)
  File "/opt/airflow/dags/etl/load.py", line 14, in carregar_parquets_para_duckdb
    con = duckdb.connect(duckdb_path)
duckdb.duckdb.IOException: IO Error: Could not set lock on file "/opt/***/data/db/duckdb_database.db": Conflicting lock is held in /usr/local/bin/python3.8 (PID 390). See also https://duckdb.org/docs/connect/concurrency
[2025-04-30T13:24:25.569+0000] {taskinstance.py:1138} INFO - Marking task as FAILED. dag_id=adm_cor_comando_ocorrencias_abertas, task_id=carregar_dados_ocorrencias_abertas, execution_date=20250430T132411, start_date=20250430T132425, end_date=20250430T132425
[2025-04-30T13:24:25.577+0000] {standard_task_runner.py:107} ERROR - Failed to execute job 258 for task carregar_dados_ocorrencias_abertas (IO Error: Could not set lock on file "/opt/***/data/db/duckdb_database.db": Conflicting lock is held in /usr/local/bin/python3.8 (PID 390). See also https://duckdb.org/docs/connect/concurrency; 391)
[2025-04-30T13:24:25.609+0000] {local_task_job_runner.py:234} INFO - Task exited with return code 1
[2025-04-30T13:24:25.622+0000] {taskinstance.py:3280} INFO - 0 downstream tasks scheduled from follow-on schedule check
