[2025-04-30T01:54:41.305+0000] {taskinstance.py:1956} INFO - Dependencies all met for dep_context=non-requeueable deps ti=<TaskInstance: clima_pluviometro_precipitacao_24h.carregar_dados manual__2025-04-30T01:54:35.313326+00:00 [queued]>
[2025-04-30T01:54:41.310+0000] {taskinstance.py:1956} INFO - Dependencies all met for dep_context=requeueable deps ti=<TaskInstance: clima_pluviometro_precipitacao_24h.carregar_dados manual__2025-04-30T01:54:35.313326+00:00 [queued]>
[2025-04-30T01:54:41.310+0000] {taskinstance.py:2170} INFO - Starting attempt 1 of 1
[2025-04-30T01:54:41.318+0000] {taskinstance.py:2191} INFO - Executing <Task(PythonOperator): carregar_dados> on 2025-04-30 01:54:35.313326+00:00
[2025-04-30T01:54:41.322+0000] {standard_task_runner.py:60} INFO - Started process 227 to run task
[2025-04-30T01:54:41.323+0000] {standard_task_runner.py:87} INFO - Running: ['***', 'tasks', 'run', 'clima_pluviometro_precipitacao_24h', 'carregar_dados', 'manual__2025-04-30T01:54:35.313326+00:00', '--job-id', '183', '--raw', '--subdir', 'DAGS_FOLDER/clima_pluviometro.py', '--cfg-path', '/tmp/tmpn0j1wif6']
[2025-04-30T01:54:41.324+0000] {standard_task_runner.py:88} INFO - Job 183: Subtask carregar_dados
[2025-04-30T01:54:41.352+0000] {task_command.py:423} INFO - Running <TaskInstance: clima_pluviometro_precipitacao_24h.carregar_dados manual__2025-04-30T01:54:35.313326+00:00 [running]> on host fdf32f9f7426
[2025-04-30T01:54:41.403+0000] {taskinstance.py:2480} INFO - Exporting env vars: AIRFLOW_CTX_DAG_OWNER='***' AIRFLOW_CTX_DAG_ID='clima_pluviometro_precipitacao_24h' AIRFLOW_CTX_TASK_ID='carregar_dados' AIRFLOW_CTX_EXECUTION_DATE='2025-04-30T01:54:35.313326+00:00' AIRFLOW_CTX_TRY_NUMBER='1' AIRFLOW_CTX_DAG_RUN_ID='manual__2025-04-30T01:54:35.313326+00:00'
[2025-04-30T01:54:41.414+0000] {logging_mixin.py:188} INFO - [clima_pluviometro.precipitacao_24h] Recriando tabela...
[2025-04-30T01:54:41.421+0000] {taskinstance.py:2698} ERROR - Task failed with exception
Traceback (most recent call last):
  File "/home/airflow/.local/lib/python3.8/site-packages/airflow/models/taskinstance.py", line 433, in _execute_task
    result = execute_callable(context=context, **execute_callable_kwargs)
  File "/home/airflow/.local/lib/python3.8/site-packages/airflow/operators/python.py", line 199, in execute
    return_value = self.execute_callable()
  File "/home/airflow/.local/lib/python3.8/site-packages/airflow/operators/python.py", line 216, in execute_callable
    return self.python_callable(*self.op_args, **self.op_kwargs)
  File "/opt/airflow/dags/etl/load.py", line 34, in carregar_parquets_para_duckdb
    con.execute(f"""
duckdb.duckdb.TransactionException: TransactionContext Error: Failed to commit: Cannot open file "/opt/***/data/db/duckdb_database.db.wal": Permission denied
[2025-04-30T01:54:41.427+0000] {taskinstance.py:1138} INFO - Marking task as FAILED. dag_id=clima_pluviometro_precipitacao_24h, task_id=carregar_dados, execution_date=20250430T015435, start_date=20250430T015441, end_date=20250430T015441
[2025-04-30T01:54:41.436+0000] {standard_task_runner.py:107} ERROR - Failed to execute job 183 for task carregar_dados (TransactionContext Error: Failed to commit: Cannot open file "/opt/***/data/db/duckdb_database.db.wal": Permission denied; 227)
[2025-04-30T01:54:41.457+0000] {local_task_job_runner.py:234} INFO - Task exited with return code 1
[2025-04-30T01:54:41.468+0000] {taskinstance.py:3280} INFO - 0 downstream tasks scheduled from follow-on schedule check
